==== WARMUP ====
WARM    RUN_CODE_ERROR        None                    
!*!*!*!*!*!*!*!*!*!*!*!*!*!*!*!*!*!*!*!*!*!*!*!*!*!*!*!*!*!*!*!*!*!*!*!*!*!*!*!*
CWD: /home/tsongpet/MSc-SSE-GI-project/_magpie_work/minisat-hack_1687202547/minisat-hack
CMD: ['run-sh/train_1.sh']
STATUS: SUCCESS
RETURN_CODE: 255
RUNTIME: 0.022860050201416016
STDOUT:
FAILED ON FILE: ../../data/circuit_fuzz/fuzz_100_25509.cnf
GOT: 1
EXPECTED: 10

STDERR:

!*!*!*!*!*!*!*!*!*!*!*!*!*!*!*!*!*!*!*!*!*!*!*!*!*!*!*!*!*!*!*!*!*!*!*!*!*!*!*!*
Magpie stopped because it was unable to run the (unmodified) target software
Self-diagnostic:
The "run_cmd" command failed with a nonzero exit code
--> try to run it manually
!*!*!*!*!*!*!*!*!*!*!*!*!*!*!*!*!*!*!*!*!*!*!*!*!*!*!*!*!*!*!*!*!*!*!*!*!*!*!*!*
==== END ====
Reason: None
Traceback (most recent call last):
  File "/usr/local/lib/python3.10/runpy.py", line 196, in _run_module_as_main
    return _run_code(code, main_globals, None,
  File "/usr/local/lib/python3.10/runpy.py", line 86, in _run_code
    exec(code, run_globals)
  File "/home/tsongpet/MSc-SSE-GI-project/bin/local_search.py", line 43, in <module>
    protocol.run()
  File "/home/tsongpet/MSc-SSE-GI-project/magpie/bin/protocol.py", line 69, in run
    self.search.run()
  File "/home/tsongpet/MSc-SSE-GI-project/magpie/algo/local_search.py", line 23, in run
    self.warmup()
  File "/home/tsongpet/MSc-SSE-GI-project/magpie/base/algorithm.py", line 145, in warmup
    raise RuntimeError('initial solution has failed')
RuntimeError: initial solution has failed
==== WARMUP ====
==== WARMUP ====
==== WARMUP ====
==== WARMUP ====
==== WARMUP ====
==== WARMUP ====
==== WARMUP ====
==== WARMUP ====
==== WARMUP ====
==== END ====
Reason: None
Traceback (most recent call last):
  File "/usr/local/lib/python3.10/runpy.py", line 196, in _run_module_as_main
    return _run_code(code, main_globals, None,
  File "/usr/local/lib/python3.10/runpy.py", line 86, in _run_code
    exec(code, run_globals)
  File "/home/tsongpet/MSc-SSE-GI-project/bin/local_search.py", line 43, in <module>
    protocol.run()
  File "/home/tsongpet/MSc-SSE-GI-project/magpie/bin/protocol.py", line 69, in run
    self.search.run()
  File "/home/tsongpet/MSc-SSE-GI-project/magpie/algo/local_search.py", line 23, in run
    self.warmup()
  File "/home/tsongpet/MSc-SSE-GI-project/magpie/base/algorithm.py", line 141, in warmup
    run = self.evaluate_patch(empty_patch, force=True)
  File "/home/tsongpet/MSc-SSE-GI-project/magpie/base/algorithm.py", line 184, in evaluate_patch
    run = self.program.evaluate_contents(contents)
  File "/home/tsongpet/MSc-SSE-GI-project/magpie/base/program.py", line 211, in evaluate_contents
WARM    RUN_TIMEOUT           None                    
!*!*!*!*!*!*!*!*!*!*!*!*!*!*!*!*!*!*!*!*!*!*!*!*!*!*!*!*!*!*!*!*!*!*!*!*!*!*!*!*
CWD: /home/tsongpet/MSc-SSE-GI-project/_magpie_work/minisat-hack_1687204009/minisat-hack
CMD: ['run-sh/train_1.sh']
STATUS: TIMEOUT
RETURN_CODE: -9
RUNTIME: 30.158660888671875
STDOUT:

STDERR:

!*!*!*!*!*!*!*!*!*!*!*!*!*!*!*!*!*!*!*!*!*!*!*!*!*!*!*!*!*!*!*!*!*!*!*!*!*!*!*!*
Magpie stopped because it was unable to run the (unmodified) target software
Self-diagnostic:
The "run_cmd" command took too long to run
--> consider increasing "run_timeout"
!*!*!*!*!*!*!*!*!*!*!*!*!*!*!*!*!*!*!*!*!*!*!*!*!*!*!*!*!*!*!*!*!*!*!*!*!*!*!*!*
==== END ====
Reason: None
Traceback (most recent call last):
  File "/usr/local/lib/python3.10/runpy.py", line 196, in _run_module_as_main
    return _run_code(code, main_globals, None,
  File "/usr/local/lib/python3.10/runpy.py", line 86, in _run_code
    exec(code, run_globals)
  File "/home/tsongpet/MSc-SSE-GI-project/bin/local_search.py", line 43, in <module>
    protocol.run()
  File "/home/tsongpet/MSc-SSE-GI-project/magpie/bin/protocol.py", line 69, in run
    self.search.run()
  File "/home/tsongpet/MSc-SSE-GI-project/magpie/algo/local_search.py", line 23, in run
    self.warmup()
  File "/home/tsongpet/MSc-SSE-GI-project/magpie/base/algorithm.py", line 145, in warmup
    raise RuntimeError('initial solution has failed')
RuntimeError: initial solution has failed
    return self.evaluate_local()
  File "/home/tsongpet/MSc-SSE-GI-project/magpie/bin/program.py", line 239, in evaluate_local
    exec_result = self.exec_cmd(shlex.split(run_cmd),
  File "/home/tsongpet/MSc-SSE-GI-project/magpie/base/program.py", line 233, in exec_cmd
    sprocess = subprocess.Popen(cmd, stdout=subprocess.PIPE, stderr=subprocess.PIPE, preexec_fn=os.setsid, env=env, shell=shell)
  File "/usr/local/lib/python3.10/subprocess.py", line 971, in __init__
    self._execute_child(args, executable, preexec_fn, close_fds,
  File "/usr/local/lib/python3.10/subprocess.py", line 1863, in _execute_child
    raise child_exception_type(errno_num, err_msg, err_filename)
PermissionError: [Errno 13] Permission denied: 'run-sh/train_3.sh'
==== WARMUP ====
==== END ====
Reason: None
Traceback (most recent call last):
  File "/usr/local/lib/python3.10/runpy.py", line 196, in _run_module_as_main
    return _run_code(code, main_globals, None,
  File "/usr/local/lib/python3.10/runpy.py", line 86, in _run_code
    exec(code, run_globals)
  File "/home/tsongpet/MSc-SSE-GI-project/bin/local_search.py", line 43, in <module>
    protocol.run()
  File "/home/tsongpet/MSc-SSE-GI-project/magpie/bin/protocol.py", line 69, in run
    self.search.run()
  File "/home/tsongpet/MSc-SSE-GI-project/magpie/algo/local_search.py", line 23, in run
    self.warmup()
  File "/home/tsongpet/MSc-SSE-GI-project/magpie/base/algorithm.py", line 141, in warmup
    run = self.evaluate_patch(empty_patch, force=True)
  File "/home/tsongpet/MSc-SSE-GI-project/magpie/base/algorithm.py", line 184, in evaluate_patch
    run = self.program.evaluate_contents(contents)
  File "/home/tsongpet/MSc-SSE-GI-project/magpie/base/program.py", line 211, in evaluate_contents
    return self.evaluate_local()
  File "/home/tsongpet/MSc-SSE-GI-project/magpie/bin/program.py", line 239, in evaluate_local
    exec_result = self.exec_cmd(shlex.split(run_cmd),
  File "/home/tsongpet/MSc-SSE-GI-project/magpie/base/program.py", line 233, in exec_cmd
    sprocess = subprocess.Popen(cmd, stdout=subprocess.PIPE, stderr=subprocess.PIPE, preexec_fn=os.setsid, env=env, shell=shell)
  File "/usr/local/lib/python3.10/subprocess.py", line 971, in __init__
    self._execute_child(args, executable, preexec_fn, close_fds,
  File "/usr/local/lib/python3.10/subprocess.py", line 1863, in _execute_child
    raise child_exception_type(errno_num, err_msg, err_filename)
PermissionError: [Errno 13] Permission denied: 'run-sh/train_4.sh'
WARM    RUN_TIMEOUT           None                    
!*!*!*!*!*!*!*!*!*!*!*!*!*!*!*!*!*!*!*!*!*!*!*!*!*!*!*!*!*!*!*!*!*!*!*!*!*!*!*!*
CWD: /home/tsongpet/MSc-SSE-GI-project/_magpie_work/minisat-hack_1687204018/minisat-hack
CMD: ['run-sh/train_2.sh']
STATUS: TIMEOUT
RETURN_CODE: -9
RUNTIME: 30.23807406425476
STDOUT:

STDERR:

!*!*!*!*!*!*!*!*!*!*!*!*!*!*!*!*!*!*!*!*!*!*!*!*!*!*!*!*!*!*!*!*!*!*!*!*!*!*!*!*
Magpie stopped because it was unable to run the (unmodified) target software
Self-diagnostic:
The "run_cmd" command took too long to run
--> consider increasing "run_timeout"
!*!*!*!*!*!*!*!*!*!*!*!*!*!*!*!*!*!*!*!*!*!*!*!*!*!*!*!*!*!*!*!*!*!*!*!*!*!*!*!*
==== END ====
Reason: None
Traceback (most recent call last):
  File "/usr/local/lib/python3.10/runpy.py", line 196, in _run_module_as_main
    return _run_code(code, main_globals, None,
  File "/usr/local/lib/python3.10/runpy.py", line 86, in _run_code
    exec(code, run_globals)
  File "/home/tsongpet/MSc-SSE-GI-project/bin/local_search.py", line 43, in <module>
    protocol.run()
  File "/home/tsongpet/MSc-SSE-GI-project/magpie/bin/protocol.py", line 69, in run
    self.search.run()
  File "/home/tsongpet/MSc-SSE-GI-project/magpie/algo/local_search.py", line 23, in run
    self.warmup()
  File "/home/tsongpet/MSc-SSE-GI-project/magpie/base/algorithm.py", line 145, in warmup
    raise RuntimeError('initial solution has failed')
RuntimeError: initial solution has failed
==== END ====
Reason: None
Traceback (most recent call last):
  File "/usr/local/lib/python3.10/runpy.py", line 196, in _run_module_as_main
    return _run_code(code, main_globals, None,
  File "/usr/local/lib/python3.10/runpy.py", line 86, in _run_code
    exec(code, run_globals)
  File "/home/tsongpet/MSc-SSE-GI-project/bin/local_search.py", line 43, in <module>
    protocol.run()
  File "/home/tsongpet/MSc-SSE-GI-project/magpie/bin/protocol.py", line 69, in run
    self.search.run()
  File "/home/tsongpet/MSc-SSE-GI-project/magpie/algo/local_search.py", line 23, in run
    self.warmup()
  File "/home/tsongpet/MSc-SSE-GI-project/magpie/base/algorithm.py", line 141, in warmup
    run = self.evaluate_patch(empty_patch, force=True)
  File "/home/tsongpet/MSc-SSE-GI-project/magpie/base/algorithm.py", line 184, in evaluate_patch
    run = self.program.evaluate_contents(contents)
  File "/home/tsongpet/MSc-SSE-GI-project/magpie/base/program.py", line 211, in evaluate_contents
    return self.evaluate_local()
  File "/home/tsongpet/MSc-SSE-GI-project/magpie/bin/program.py", line 239, in evaluate_local
    exec_result = self.exec_cmd(shlex.split(run_cmd),
  File "/home/tsongpet/MSc-SSE-GI-project/magpie/base/program.py", line 233, in exec_cmd
    sprocess = subprocess.Popen(cmd, stdout=subprocess.PIPE, stderr=subprocess.PIPE, preexec_fn=os.setsid, env=env, shell=shell)
  File "/usr/local/lib/python3.10/subprocess.py", line 971, in __init__
    self._execute_child(args, executable, preexec_fn, close_fds,
  File "/usr/local/lib/python3.10/subprocess.py", line 1863, in _execute_child
    raise child_exception_type(errno_num, err_msg, err_filename)
PermissionError: [Errno 13] Permission denied: 'run-sh/train_5.sh'
==== END ====
Reason: None
Traceback (most recent call last):
  File "/usr/local/lib/python3.10/runpy.py", line 196, in _run_module_as_main
    return _run_code(code, main_globals, None,
  File "/usr/local/lib/python3.10/runpy.py", line 86, in _run_code
    exec(code, run_globals)
  File "/home/tsongpet/MSc-SSE-GI-project/bin/local_search.py", line 43, in <module>
    protocol.run()
  File "/home/tsongpet/MSc-SSE-GI-project/magpie/bin/protocol.py", line 69, in run
    self.search.run()
  File "/home/tsongpet/MSc-SSE-GI-project/magpie/algo/local_search.py", line 23, in run
    self.warmup()
  File "/home/tsongpet/MSc-SSE-GI-project/magpie/base/algorithm.py", line 141, in warmup
    run = self.evaluate_patch(empty_patch, force=True)
  File "/home/tsongpet/MSc-SSE-GI-project/magpie/base/algorithm.py", line 184, in evaluate_patch
    run = self.program.evaluate_contents(contents)
  File "/home/tsongpet/MSc-SSE-GI-project/magpie/base/program.py", line 211, in evaluate_contents
    return self.evaluate_local()
  File "/home/tsongpet/MSc-SSE-GI-project/magpie/bin/program.py", line 239, in evaluate_local
    exec_result = self.exec_cmd(shlex.split(run_cmd),
  File "/home/tsongpet/MSc-SSE-GI-project/magpie/base/program.py", line 233, in exec_cmd
    sprocess = subprocess.Popen(cmd, stdout=subprocess.PIPE, stderr=subprocess.PIPE, preexec_fn=os.setsid, env=env, shell=shell)
  File "/usr/local/lib/python3.10/subprocess.py", line 971, in __init__
    self._execute_child(args, executable, preexec_fn, close_fds,
  File "/usr/local/lib/python3.10/subprocess.py", line 1863, in _execute_child
    raise child_exception_type(errno_num, err_msg, err_filename)
PermissionError: [Errno 13] Permission denied: 'run-sh/train_6.sh'
==== END ====
Reason: None
Traceback (most recent call last):
  File "/usr/local/lib/python3.10/runpy.py", line 196, in _run_module_as_main
    return _run_code(code, main_globals, None,
  File "/usr/local/lib/python3.10/runpy.py", line 86, in _run_code
    exec(code, run_globals)
  File "/home/tsongpet/MSc-SSE-GI-project/bin/local_search.py", line 43, in <module>
    protocol.run()
  File "/home/tsongpet/MSc-SSE-GI-project/magpie/bin/protocol.py", line 69, in run
    self.search.run()
  File "/home/tsongpet/MSc-SSE-GI-project/magpie/algo/local_search.py", line 23, in run
    self.warmup()
  File "/home/tsongpet/MSc-SSE-GI-project/magpie/base/algorithm.py", line 141, in warmup
    run = self.evaluate_patch(empty_patch, force=True)
  File "/home/tsongpet/MSc-SSE-GI-project/magpie/base/algorithm.py", line 184, in evaluate_patch
    run = self.program.evaluate_contents(contents)
  File "/home/tsongpet/MSc-SSE-GI-project/magpie/base/program.py", line 211, in evaluate_contents
    return self.evaluate_local()
  File "/home/tsongpet/MSc-SSE-GI-project/magpie/bin/program.py", line 239, in evaluate_local
    exec_result = self.exec_cmd(shlex.split(run_cmd),
  File "/home/tsongpet/MSc-SSE-GI-project/magpie/base/program.py", line 233, in exec_cmd
    sprocess = subprocess.Popen(cmd, stdout=subprocess.PIPE, stderr=subprocess.PIPE, preexec_fn=os.setsid, env=env, shell=shell)
  File "/usr/local/lib/python3.10/subprocess.py", line 971, in __init__
    self._execute_child(args, executable, preexec_fn, close_fds,
  File "/usr/local/lib/python3.10/subprocess.py", line 1863, in _execute_child
    raise child_exception_type(errno_num, err_msg, err_filename)
PermissionError: [Errno 13] Permission denied: 'run-sh/train_7.sh'
==== END ====
Reason: None
Traceback (most recent call last):
  File "/usr/local/lib/python3.10/runpy.py", line 196, in _run_module_as_main
    return _run_code(code, main_globals, None,
  File "/usr/local/lib/python3.10/runpy.py", line 86, in _run_code
    exec(code, run_globals)
  File "/home/tsongpet/MSc-SSE-GI-project/bin/local_search.py", line 43, in <module>
    protocol.run()
  File "/home/tsongpet/MSc-SSE-GI-project/magpie/bin/protocol.py", line 69, in run
    self.search.run()
  File "/home/tsongpet/MSc-SSE-GI-project/magpie/algo/local_search.py", line 23, in run
    self.warmup()
  File "/home/tsongpet/MSc-SSE-GI-project/magpie/base/algorithm.py", line 141, in warmup
    run = self.evaluate_patch(empty_patch, force=True)
  File "/home/tsongpet/MSc-SSE-GI-project/magpie/base/algorithm.py", line 184, in evaluate_patch
    run = self.program.evaluate_contents(contents)
  File "/home/tsongpet/MSc-SSE-GI-project/magpie/base/program.py", line 211, in evaluate_contents
    return self.evaluate_local()
  File "/home/tsongpet/MSc-SSE-GI-project/magpie/bin/program.py", line 239, in evaluate_local
    exec_result = self.exec_cmd(shlex.split(run_cmd),
  File "/home/tsongpet/MSc-SSE-GI-project/magpie/base/program.py", line 233, in exec_cmd
    sprocess = subprocess.Popen(cmd, stdout=subprocess.PIPE, stderr=subprocess.PIPE, preexec_fn=os.setsid, env=env, shell=shell)
  File "/usr/local/lib/python3.10/subprocess.py", line 971, in __init__
    self._execute_child(args, executable, preexec_fn, close_fds,
  File "/usr/local/lib/python3.10/subprocess.py", line 1863, in _execute_child
    raise child_exception_type(errno_num, err_msg, err_filename)
PermissionError: [Errno 13] Permission denied: 'run-sh/train_8.sh'
==== END ====
Reason: None
Traceback (most recent call last):
  File "/usr/local/lib/python3.10/runpy.py", line 196, in _run_module_as_main
    return _run_code(code, main_globals, None,
  File "/usr/local/lib/python3.10/runpy.py", line 86, in _run_code
    exec(code, run_globals)
  File "/home/tsongpet/MSc-SSE-GI-project/bin/local_search.py", line 43, in <module>
    protocol.run()
  File "/home/tsongpet/MSc-SSE-GI-project/magpie/bin/protocol.py", line 69, in run
    self.search.run()
  File "/home/tsongpet/MSc-SSE-GI-project/magpie/algo/local_search.py", line 23, in run
    self.warmup()
  File "/home/tsongpet/MSc-SSE-GI-project/magpie/base/algorithm.py", line 141, in warmup
    run = self.evaluate_patch(empty_patch, force=True)
  File "/home/tsongpet/MSc-SSE-GI-project/magpie/base/algorithm.py", line 184, in evaluate_patch
    run = self.program.evaluate_contents(contents)
  File "/home/tsongpet/MSc-SSE-GI-project/magpie/base/program.py", line 211, in evaluate_contents
    return self.evaluate_local()
  File "/home/tsongpet/MSc-SSE-GI-project/magpie/bin/program.py", line 239, in evaluate_local
    exec_result = self.exec_cmd(shlex.split(run_cmd),
  File "/home/tsongpet/MSc-SSE-GI-project/magpie/base/program.py", line 233, in exec_cmd
    sprocess = subprocess.Popen(cmd, stdout=subprocess.PIPE, stderr=subprocess.PIPE, preexec_fn=os.setsid, env=env, shell=shell)
  File "/usr/local/lib/python3.10/subprocess.py", line 971, in __init__
    self._execute_child(args, executable, preexec_fn, close_fds,
  File "/usr/local/lib/python3.10/subprocess.py", line 1863, in _execute_child
    raise child_exception_type(errno_num, err_msg, err_filename)
PermissionError: [Errno 13] Permission denied: 'run-sh/train_9.sh'
==== END ====
Reason: None
Traceback (most recent call last):
  File "/usr/local/lib/python3.10/runpy.py", line 196, in _run_module_as_main
    return _run_code(code, main_globals, None,
  File "/usr/local/lib/python3.10/runpy.py", line 86, in _run_code
    exec(code, run_globals)
  File "/home/tsongpet/MSc-SSE-GI-project/bin/local_search.py", line 43, in <module>
    protocol.run()
  File "/home/tsongpet/MSc-SSE-GI-project/magpie/bin/protocol.py", line 69, in run
    self.search.run()
  File "/home/tsongpet/MSc-SSE-GI-project/magpie/algo/local_search.py", line 23, in run
    self.warmup()
  File "/home/tsongpet/MSc-SSE-GI-project/magpie/base/algorithm.py", line 141, in warmup
    run = self.evaluate_patch(empty_patch, force=True)
  File "/home/tsongpet/MSc-SSE-GI-project/magpie/base/algorithm.py", line 184, in evaluate_patch
    run = self.program.evaluate_contents(contents)
  File "/home/tsongpet/MSc-SSE-GI-project/magpie/base/program.py", line 211, in evaluate_contents
    return self.evaluate_local()
  File "/home/tsongpet/MSc-SSE-GI-project/magpie/bin/program.py", line 239, in evaluate_local
    exec_result = self.exec_cmd(shlex.split(run_cmd),
  File "/home/tsongpet/MSc-SSE-GI-project/magpie/base/program.py", line 233, in exec_cmd
    sprocess = subprocess.Popen(cmd, stdout=subprocess.PIPE, stderr=subprocess.PIPE, preexec_fn=os.setsid, env=env, shell=shell)
  File "/usr/local/lib/python3.10/subprocess.py", line 971, in __init__
    self._execute_child(args, executable, preexec_fn, close_fds,
  File "/usr/local/lib/python3.10/subprocess.py", line 1863, in _execute_child
    raise child_exception_type(errno_num, err_msg, err_filename)
PermissionError: [Errno 13] Permission denied: 'run-sh/train_10.sh'
